Workbook

Sheet RAW
A1: OrderID | B1: Date | C1: CustomerID | D1: Product | E1: Quantity | F1: UnitPrice | G1: ShippingAddress | H1: PaymentMethod | I1: OrderStatus | J1: TrackingNumber | K1: ItemsInCart | L1: CouponCode | M1: ReferralSource | N1: TotalPrice
A2: ORD200000 | B2: 44930 | C2: C72649 | D2: Monitor | E2: 5 | F2: 570.62 | G2: 928 Main St | H2: Debit Card | I2: Shipped | J2: TRK37947903 | K2: 7 | L2: SAVE10 | M2: Instagram | N2: 2853.1
A3: ORD200001 | B3: 45527 | C3: C75739 | D3: Phone | E3: 2 | F3: 151.35 | G3: 823 Main St | H3: Online | I3: Shipped | J3: TRK91186779 | K3: 3 | L3: SAVE10 | M3: Referral | N3: 302.7
A4: ORD200002 | B4: 45349 | C4: C81728 | D4: Tablet | E4: 5 | F4: 550.68 | G4: 512 Main St | H4: Credit Card | I4: Cancelled | J4: TRK42903982 | K4: 8 | L4: FREESHIP | M4: Email | N4: 2753.4
A5: ORD200003 | B5: 45214 | C5: C33540 | D5: Chair | E5: 1 | F5: 273.19 | G5: 275 Main St | H5: Debit Card | I5: Returned | J5: TRK62788070 | K5: 5 | L5: SAVE10 | M5: Facebook | N5: 273.19
A6: ORD200004 | B6: 45785 | C6: C81840 | D6: Printer | E6: 4 | F6: 626.01 | G6: 668 Main St | H6: Online | I6: Delivered | J6: TRK29241424 | K6: 8 | L6: SAVE10 | M6: Email | N6: 2504.04
A7: ORD200005 | B7: 45222 | C7: C37249 | D7: Phone | E7: 2 | F7: 245.86 | G7: 934 Main St | H7: Credit Card | I7: Shipped | J7: TRK72976927 | K7: 4 | L7: SAVE10 | M7: Instagram | N7: 491.72
A8: ORD200006 | B8: 45825 | C8: C83492 | D8: Laptop | E8: 1 | F8: 664.42 | G8: 986 Main St | H8: Gift Card | I8: Returned | J8: TRK96417362 | K8: 6 | L8: SAVE10 | M8: Facebook | N8: 664.42
A9: ORD200007 | B9: 45058 | C9: C41460 | D9: Monitor | E9: 5 | F9: 149.55 | G9: 706 Main St | H9: Cash | I9: Shipped | J9: TRK78809193 | K9: 9 | L9: FREESHIP | M9: Facebook | N9: 747.75
A10: ORD200008 | B10: 45749 | C10: C26817 | D10: Phone | E10: 2 | F10: 134.28 | G10: 904 Main St | H10: Gift Card | I10: Cancelled | J10: TRK61042692 | K10: 2 | M10: Email | N10: 268.56
A11: ORD200009 | B11: 45251 | C11: C31946 | D11: Desk | E11: 4 | F11: 509.38 | G11: 102 Main St | H11: Credit Card | I11: Shipped | J11: TRK33478363 | K11: 6 | L11: SAVE10 | M11: Google | N11: 2037.52
A12: ORD200010 | B12: 45289 | C12: C43443 | D12: Tablet | E12: 5 | F12: 625.97 | G12: 333 Main St | H12: Credit Card | I12: Returned | J12: TRK98859248 | K12: 9 | L12: WINTER15 | M12: Instagram | N12: 3129.85
A13: ORD200011 | B13: 45339 | C13: C93861 | D13: Monitor | E13: 3 | F13: 49.14 | G13: 831 Main St | H13: Online | I13: Returned | J13: TRK48234646 | K13: 7 | L13: SAVE10 | M13: Email | N13: 147.42
A14: ORD200012 | B14: 45580 | C14: C38785 | D14: Monitor | E14: 2 | F14: 180.5 | G14: 179 Main St | H14: Debit Card | I14: Pending | J14: TRK20419991 | K14: 6 | L14: FREESHIP | M14: Referral | N14: 361
A15: ORD200013 | B15: 45168 | C15: C88348 | D15: Laptop | E15: 3 | F15: 201.49 | G15: 903 Main St | H15: Credit Card | I15: Returned | J15: TRK81913874 | K15: 4 | L15: FREESHIP | M15: Facebook | N15: 604.47
A16: ORD200014 | B16: 45012 | C16: C98474 | D16: Tablet | E16: 2 | F16: 393.33 | G16: 980 Main St | H16: Debit Card | I16: Pending | J16: TRK79186539 | K16: 3 | L16: SAVE10 | M16: Instagram | N16: 786.66
A17: ORD200015 | B17: 45124 | C17: C39416 | D17: Printer | E17: 1 | F17: 473.96 | G17: 942 Main St | H17: Cash | I17: Delivered | J17: TRK54930938 | K17: 3 | M17: Google | N17: 473.96
A18: ORD200016 | B18: 44950 | C18: C28976 | D18: Printer | E18: 2 | F18: 533.81 | G18: 914 Main St | H18: Credit Card | I18: Pending | J18: TRK13194259 | K18: 3 | L18: FREESHIP | M18: Email | N18: 1067.62
A19: ORD200017 | B19: 45353 | C19: C60672 | D19: Tablet | E19: 1 | F19: 423.4 | G19: 382 Main St | H19: Debit Card | I19: Shipped | J19: TRK11972116 | K19: 3 | M19: Referral | N19: 423.4
A20: ORD200018 | B20: 45742 | C20: C84329 | D20: Desk | E20: 1 | F20: 431.44 | G20: 891 Main St | H20: Gift Card | I20: Pending | J20: TRK65191045 | K20: 3 | L20: SAVE10 | M20: Facebook | N20: 431.44
A21: ORD200019 | B21: 44949 | C21: C14552 | D21: Monitor | E21: 5 | F21: 224 | G21: 273 Main St | H21: Cash | I21: Returned | J21: TRK59101365 | K21: 9 | L21: SAVE10 | M21: Google | N21: 1120
A22: ORD200020 | B22: 45054 | C22: C54829 | D22: Chair | E22: 5 | F22: 62.51 | G22: 587 Main St | H22: Cash | I22: Pending | J22: TRK16718651 | K22: 9 | L22: WINTER15 | M22: Instagram | N22: 312.55
A23: ORD200021 | B23: 45613 | C23: C99023 | D23: Monitor | E23: 4 | F23: 342.95 | G23: 569 Main St | H23: Cash | I23: Delivered | J23: TRK52646983 | K23: 6 | M23: Google | N23: 1371.8
A24: ORD200022 | B24: 44955 | C24: C34416 | D24: Monitor | E24: 2 | F24: 49.62 | G24: 633 Main St | H24: Online | I24: Pending | J24: TRK75937350 | K24: 2 | L24: SAVE10 | M24: Google | N24: 99.24
A25: ORD200023 | B25: 45756 | C25: C42372 | D25: Phone | E25: 4 | F25: 273.25 | G25: 755 Main St | H25: Debit Card | I25: Cancelled | J25: TRK36168083 | K25: 5 | L25: FREESHIP | M25: Referral | N25: 1093
A26: ORD200024 | B26: 45595 | C26: C17470 | D26: Laptop | E26: 2 | F26: 230.95 | G26: 956 Main St | H26: Online | I26: Delivered | J26: TRK28775057 | K26: 3 | L26: WINTER15 | M26: Referral | N26: 461.9
A27: ORD200025 | B27: 45497 | C27: C42577 | D27: Monitor | E27: 1 | F27: 399.98 | G27: 709 Main St | H27: Debit Card | I27: Delivered | J27: TRK69423327 | K27: 3 | L27: WINTER15 | M27: Email | N27: 399.98
A28: ORD200026 | B28: 45357 | C28: C21944 | D28: Laptop | E28: 5 | F28: 59.55 | G28: 296 Main St | H28: Online | I28: Delivered | J28: TRK80276812 | K28: 6 | M28: Referral | N28: 297.75
A29: ORD200027 | B29: 45344 | C29: C97593 | D29: Printer | E29: 1 | F29: 472.74 | G29: 881 Main St | H29: Online | I29: Shipped | J29: TRK89117573 | K29: 6 | L29: WINTER15 | M29: Google | N29: 472.74
A30: ORD200028 | B30: 45251 | C30: C59823 | D30: Phone | E30: 4 | F30: 160.07 | G30: 568 Main St | H30: Online | I30: Pending | J30: TRK65895539 | K30: 5 | M30: Email | N30: 640.28
A31: ORD200029 | B31: 45555 | C31: C33260 | D31: Desk | E31: 3 | F31: 423.53 | G31: 930 Main St | H31: Credit Card | I31: Delivered | J31: TRK59744090 | K31: 6 | L31: SAVE10 | M31: Referral | N31: 1270.59
A32: ORD200030 | B32: 45738 | C32: C44267 | D32: Monitor | E32: 2 | F32: 426.7 | G32: 895 Main St | H32: Online | I32: Pending | J32: TRK54751444 | K32: 5 | L32: SAVE10 | M32: Referral | N32: 853.4
A33: ORD200031 | B33: 45107 | C33: C26445 | D33: Chair | E33: 3 | F33: 500.08 | G33: 996 Main St | H33: Debit Card | I33: Returned | J33: TRK31229981 | K33: 6 | M33: Facebook | N33: 1500.24
A34: ORD200032 | B34: 45047 | C34: C12388 | D34: Tablet | E34: 5 | F34: 536.72 | G34: 830 Main St | H34: Cash | I34: Delivered | J34: TRK99261395 | K34: 10 | M34: Email | N34: 2683.6
A35: ORD200033 | B35: 45082 | C35: C52184 | D35: Chair | E35: 1 | F35: 162.77 | G35: 912 Main St | H35: Online | I35: Cancelled | J35: TRK73312471 | K35: 4 | L35: WINTER15 | M35: Facebook | N35: 162.77
A36: ORD200034 | B36: 44933 | C36: C67195 | D36: Chair | E36: 4 | F36: 576.52 | G36: 926 Main St | H36: Credit Card | I36: Pending | J36: TRK55467915 | K36: 5 | L36: WINTER15 | M36: Facebook | N36: 2306.08
A37: ORD200035 | B37: 45633 | C37: C50304 | D37: Monitor | E37: 2 | F37: 465.15 | G37: 128 Main St | H37: Online | I37: Shipped | J37: TRK46850888 | K37: 2 | L37: SAVE10 | M37: Facebook | N37: 930.3
A38: ORD200036 | B38: 45785 | C38: C59337 | D38: Laptop | E38: 2 | F38: 534.43 | G38: 465 Main St | H38: Debit Card | I38: Pending | J38: TRK50961250 | K38: 5 | M38: Facebook | N38: 1068.86
A39: ORD200037 | B39: 45579 | C39: C10054 | D39: Laptop | E39: 2 | F39: 76.74 | G39: 409 Main St | H39: Cash | I39: Returned | J39: TRK94005261 | K39: 7 | L39: SAVE10 | M39: Instagram | N39: 153.48
A40: ORD200038 | B40: 45645 | C40: C15924 | D40: Laptop | E40: 1 | F40: 245.89 | G40: 549 Main St | H40: Debit Card | I40: Delivered | J40: TRK14835975 | K40: 3 | L40: SAVE10 | M40: Google | N40: 245.89
...

Sheet CLEANED
A1: OrderID | B1: Date | C1: CustomerID | D1: Product | E1: Quantity | F1: UnitPrice | G1: ShippingAddress | H1: PaymentMethod | I1: OrderStatus | J1: TrackingNumber | K1: ItemsInCart | L1: CouponCode | M1: ReferralSource | N1: TotalPrice
A2: ORD200000 | B2: 44930 | C2: C72649 | D2: Monitor | E2: 5 | F2: 570.62 | G2: 928 Main St | H2: Debit Card | I2: Shipped | J2: TRK37947903 | K2: 7 | L2: SAVE10 | M2: Instagram | N2: 2853.1
A3: ORD200001 | B3: 45527 | C3: C75739 | D3: Phone | E3: 2 | F3: 151.35 | G3: 823 Main St | H3: Online | I3: Shipped | J3: TRK91186779 | K3: 3 | L3: SAVE10 | M3: Referral | N3: 302.7
A4: ORD200002 | B4: 45349 | C4: C81728 | D4: Tablet | E4: 5 | F4: 550.68 | G4: 512 Main St | H4: Credit Card | I4: Cancelled | J4: TRK42903982 | K4: 8 | L4: FREESHIP | M4: Email | N4: 2753.4
A5: ORD200003 | B5: 45214 | C5: C33540 | D5: Chair | E5: 1 | F5: 273.19 | G5: 275 Main St | H5: Debit Card | I5: Returned | J5: TRK62788070 | K5: 5 | L5: SAVE10 | M5: Facebook | N5: 273.19
A6: ORD200004 | B6: 45785 | C6: C81840 | D6: Printer | E6: 4 | F6: 626.01 | G6: 668 Main St | H6: Online | I6: Delivered | J6: TRK29241424 | K6: 8 | L6: SAVE10 | M6: Email | N6: 2504.04
A7: ORD200005 | B7: 45222 | C7: C37249 | D7: Phone | E7: 2 | F7: 245.86 | G7: 934 Main St | H7: Credit Card | I7: Shipped | J7: TRK72976927 | K7: 4 | L7: SAVE10 | M7: Instagram | N7: 491.72
A8: ORD200006 | B8: 45825 | C8: C83492 | D8: Laptop | E8: 1 | F8: 664.42 | G8: 986 Main St | H8: Gift Card | I8: Returned | J8: TRK96417362 | K8: 6 | L8: SAVE10 | M8: Facebook | N8: 664.42
A9: ORD200007 | B9: 45058 | C9: C41460 | D9: Monitor | E9: 5 | F9: 149.55 | G9: 706 Main St | H9: Cash | I9: Shipped | J9: TRK78809193 | K9: 9 | L9: FREESHIP | M9: Facebook | N9: 747.75
A10: ORD200008 | B10: 45749 | C10: C26817 | D10: Phone | E10: 2 | F10: 134.28 | G10: 904 Main St | H10: Gift Card | I10: Cancelled | J10: TRK61042692 | K10: 2 | L10: NO COUPON | M10: Email | N10: 268.56
A11: ORD200009 | B11: 45251 | C11: C31946 | D11: Desk | E11: 4 | F11: 509.38 | G11: 102 Main St | H11: Credit Card | I11: Shipped | J11: TRK33478363 | K11: 6 | L11: SAVE10 | M11: Google | N11: 2037.52
A12: ORD200010 | B12: 45289 | C12: C43443 | D12: Tablet | E12: 5 | F12: 625.97 | G12: 333 Main St | H12: Credit Card | I12: Returned | J12: TRK98859248 | K12: 9 | L12: WINTER15 | M12: Instagram | N12: 3129.85
A13: ORD200011 | B13: 45339 | C13: C93861 | D13: Monitor | E13: 3 | F13: 49.14 | G13: 831 Main St | H13: Online | I13: Returned | J13: TRK48234646 | K13: 7 | L13: SAVE10 | M13: Email | N13: 147.42
... A1201: ORD201199 | B1201: 45088 | C1201: C57502 | D1201: Tablet | E1201: 4 | F1201: 560.58 | G1201: 201 Main St | H1201: Gift Card | I1201: Returned | J1201: TRK51116746 | K1201: 6 | L1201: SAVE10 | M1201: Referral | N1201: 2242.32

Sheet PROJECT 2
A1: OrderID | B1: Date | C1: CustomerID | D1: Product | E1: Quantity | F1: UnitPrice | G1: ShippingAddress | H1: PaymentMethod | I1: OrderStatus | J1: TrackingNumber | K1: ItemsInCart | L1: CouponCode | M1: ReferralSource | N1: TotalPrice
A2: ORD200000 | B2: 44930 | C2: C72649 | D2: Monitor | E2: 5 | F2: 570.62 | G2: 928 Main St | H2: Debit Card | I2: Shipped | J2: TRK37947903 | K2: 7 | L2: SAVE10 | M2: Instagram | N2: 2853.1
A3: ORD200001 | B3: 45527 | C3: C75739 | D3: Phone | E3: 2 | F3: 151.35 | G3: 823 Main St | H3: Online | I3: Shipped | J3: TRK91186779 | K3: 3 | L3: SAVE10 | M3: Referral | N3: 302.7
A4: ORD200002 | B4: 45349 | C4: C81728 | D4: Tablet | E4: 5 | F4: 550.68 | G4: 512 Main St | H4: Credit Card | I4: Cancelled | J4: TRK42903982 | K4: 8 | L4: FREESHIP | M4: Email | N4: 2753.4
A5: ORD200003 | B5: 45214 | C5: C33540 | D5: Chair | E5: 1 | F5: 273.19 | G5: 275 Main St | H5: Debit Card | I5: Returned | J5: TRK62788070 | K5: 5 | L5: SAVE10 | M5: Facebook | N5: 273.19
A6: ORD200004 | B6: 45785 | C6: C81840 | D6: Printer | E6: 4 | F6: 626.01 | G6: 668 Main St | H6: Online | I6: Delivered | J6: TRK29241424 | K6: 8 | L6: SAVE10 | M6: Email | N6: 2504.04
A7: ORD200005 | B7: 45222 | C7: C37249 | D7: Phone | E7: 2 | F7: 245.86 | G7: 934 Main St | H7: Credit Card | I7: Shipped | J7: TRK72976927 | K7: 4 | L7: SAVE10 | M7: Instagram | N7: 491.72
A8: ORD200006 | B8: 45825 | C8: C83492 | D8: Laptop | E8: 1 | F8: 664.42 | G8: 986 Main St | H8: Gift Card | I8: Returned | J8: TRK96417362 | K8: 6 | L8: SAVE10 | M8: Facebook | N8: 664.42
A9: ORD200007 | B9: 45058 | C9: C41460 | D9: Monitor | E9: 5 | F9: 149.55 | G9: 706 Main St | H9: Cash | I9: Shipped | J9: TRK78809193 | K9: 9 | L9: FREESHIP | M9: Facebook | N9: 747.75
A10: ORD200008 | B10: 45749 | C10: C26817 | D10: Phone | E10: 2 | F10: 134.28 | G10: 904 Main St | H10: Gift Card | I10: Cancelled | J10: TRK61042692 | K10: 2 | L10: NO COUPON | M10: Email | N10: 268.56
A11: ORD200009 | B11: 45251 | C11: C31946 | D11: Desk | E11: 4 | F11: 509.38 | G11: 102 Main St | H11: Credit Card | I11: Shipped | J11: TRK33478363 | K11: 6 | L11: SAVE10 | M11: Google | N11: 2037.52
A12: ORD200010 | B12: 45289 | C12: C43443 | D12: Tablet | E12: 5 | F12: 625.97 | G12: 333 Main St | H12: Credit Card | I12: Returned | J12: TRK98859248 | K12: 9 | L12: WINTER15 | M12: Instagram | N12: 3129.85
A13: ORD200011 | B13: 45339 | C13: C93861 | D13: Monitor | E13: 3 | F13: 49.14 | G13: 831 Main St | H13: Online | I13: Returned | J13: TRK48234646 | K13: 7 | L13: SAVE10 | M13: Email | N13: 147.42
... A1201: ORD201199 | B1201: 45088 | C1201: C57502 | D1201: Tablet | E1201: 4 | F1201: 560.58 | G1201: 201 Main St | H1201: Gift Card | I1201: Returned | J1201: TRK51116746 | K1201: 6 | L1201: SAVE10 | M1201: Referral | N1201: 2242.32

Sheet BASIC STATS
A1: Basic Statistics ( Quantity, Unit Price, Total Price)
A3: METRICS | B3: QUANTITY | C3: UNIT PRICE | D3: TOTAL PRICE
A4: Average | B4: =AVERAGE('PROJECT 2'!E:E) -> 2.9458333 | C4: =AVERAGE('PROJECT 2'!F:F) -> 356.41275 | D4: =AVERAGE('PROJECT 2'!N:N) -> 1053.9683
A5: Median | B5: =MEDIAN('PROJECT 2'!E:E) -> 3 | C5: =MEDIAN('PROJECT 2'!F:F) -> 364.21 | D5: =MEDIAN('PROJECT 2'!N:N) -> 823.615
A6: Std | B6: =_xlfn.STDEV.S('PROJECT 2'!E:E) -> 1.4075571 | C6: =_xlfn.STDEV.S('PROJECT 2'!F:F) -> 197.17715 | D6: =_xlfn.STDEV.S('PROJECT 2'!N:N) -> 819.85656
A7: Count | B7: =COUNT('PROJECT 2'!E:E) -> 1200 | C7: =COUNT('PROJECT 2'!F:F) -> 1200 | D7: =COUNT('PROJECT 2'!N:N) -> 1200
A8: Minimum | B8: =MIN('PROJECT 2'!E:E) -> 1 | C8: =MIN('PROJECT 2'!F:F) -> 11.39 | D8: =MIN('PROJECT 2'!N:N) -> 11.39
A9: Maximum | B9: =MAX('PROJECT 2'!E:E) -> 5 | C9: =MAX('PROJECT 2'!F:F) -> 699.93 | D9: =MAX('PROJECT 2'!N:N) -> 3456.4

Sheet OUTLIER
B2: OUTLIER ORDERS (TOTAL PRICE USING IQR METHOD)
B3: Quartile 1(Q1) | D3: =_xlfn.QUARTILE.INC('PROJECT 2'!N:N,1) -> 410.52
B4: Quartile 3(Q3) | D4: =_xlfn.QUARTILE.INC('PROJECT 2'!N:N,3) -> 1578.475
B5: Interquartile Range(IQR) | D5: =D4-D3 -> 1167.955
B6: Upper Bound | D6: =D4+(1.5*D5) -> 3330.4075
B7: lower Bound | D7: =D3-(1.5*D5) -> -1341.4125
B8: Outlier Count | D8: =COUNTIF('PROJECT 2'!N:N,">3330.41") -> 8
B11: ORDER_ID | C11: DATE | D11: CUSTOMER_ID | E11: PRODUCT | G11: TOTAL_PRICE | H11: OUTLIER REASON
B12: ORD200107 | C12: 45012 | D12: C16775 | E12: Printer | G12: 3353.75 | H12: Above upper bound(3,330.41)
B13: ORD200326 | C13: 45474 | D13: C65986 | E13: Laptop | G13: 3352.4 | H13: Above upper bound(3,330.41)
B14: ORD200328 | C14: 44985 | D14: C18404 | E14: Tablet | G14: 3370.2 | H14: Above upper bound(3,330.41)
B15: ORD200469 | C15: 45256 | D15: C13877 | E15: Chair | G15: 3384.9 | H15: Above upper bound(3,330.41)
B16: ORD200632 | C16: 45048 | D16: C67260 | E16: Laptop | G16: 3390.8 | H16: Above upper bound(3,330.41)
B17: ORD200789 | C17: 45155 | D17: C57276 | E17: Tablet | G17: 3456.4 | H17: Above upper bound(3,330.41)
B18: ORD201065 | C18: 45229 | D18: C47778 | E18: Printer | G18: 3334 | H18: Above upper bound(3,330.41)
B19: ORD201122 | C19: 45084 | D19: C38840 | E19: Monitor | G19: 3390.95 | H19: Above upper bound(3,330.41)

Sheet CORRELATION
C2: QUANTITY | E2: UNITPRICE | G2: TOTALPRICE | I2: ITEMINCART
B4: QUANTITY | C4: 1 | E4: =CORREL(CLEANED!E2:E1201, CLEANED!F2:F1201) -> 0.014553341 | G4: =CORREL(CLEANED!E2:E1201, CLEANED!N2:N1201) -> 0.61525136 | I4: =CORREL(CLEANED!E2:E1201, CLEANED!K2:K1201) -> 0.65006123
B6: UNITPRICE | C6: =CORREL(CLEANED!E2:E1201, CLEANED!F2:F1201) -> 0.014553341 | E6: 1 | G6: =CORREL(CLEANED!F2:F1201, CLEANED!N2:N1201) -> 0.71708109 | I6: =CORREL(CLEANED!E2:E1201, CLEANED!K2:K1201) -> 0.65006123
B8: TOTALPRICE | C8: =CORREL(CLEANED!E2:E1201, CLEANED!N2:N1201) -> 0.61525136 | E8: =CORREL(CLEANED!F2:F1201, CLEANED!N2:N1201) -> 0.71708109 | G8: 1 | I8: =CORREL(CLEANED!N2:N1201, CLEANED!K2:K1201) -> 0.39254026
B10: ITEMINCART | C10: =CORREL(CLEANED!E2:E1201, CLEANED!K2:K1201) -> 0.65006123 | E10: =CORREL(CLEANED!F2:F1201, CLEANED!K2:K1201) -> 0.00060215368 | G10: =CORREL(CLEANED!N2:N1201, CLEANED!K2:K1201) -> 0.39254026 | I10: 1

Sheet SUMMARY TABLE
B1: REVENUE & ORDERS BY PRODUCT
A2: PRODUCT | B2: ORDER COUNT | C2: TOTAL REVENUE | D2: AVERAGE ORDER VALUE
A3: Chair | B3: =COUNTIF(CLEANED!$D$2:$D$1201, A3) -> 178 | C3: =SUMIF(CLEANED!$D$2:$D$1201, A3, CLEANED!$N$2:$N$1201) -> 195620.11 | D3: =AVERAGEIF(CLEANED!$D$2:$D$1201, A3, CLEANED!$N$2:$N$1201) -> 1098.9894
A4: Desk | B4: =COUNTIF(CLEANED!$D$2:$D$1201, A4) -> 170 | C4: =SUMIF(CLEANED!$D$2:$D$1201, A4, CLEANED!$N$2:$N$1201) -> 167459.93 | D4: =AVERAGEIF(CLEANED!$D$2:$D$1201, A4, CLEANED!$N$2:$N$1201) -> 985.05841
A5: Laptop | B5: =COUNTIF(CLEANED!$D$2:$D$1201, A5) -> 173 | C5: =SUMIF(CLEANED!$D$2:$D$1201, A5, CLEANED!$N$2:$N$1201) -> 192126.56 | D5: =AVERAGEIF(CLEANED!$D$2:$D$1201, A5, CLEANED!$N$2:$N$1201) -> 1110.5582
A6: Monitor | B6: =COUNTIF(CLEANED!$D$2:$D$1201, A6) -> 163 | C6: =SUMIF(CLEANED!$D$2:$D$1201, A6, CLEANED!$N$2:$N$1201) -> 175651.41 | D6: =AVERAGEIF(CLEANED!$D$2:$D$1201, A6, CLEANED!$N$2:$N$1201) -> 1077.616
A7: Phone | B7: =COUNTIF(CLEANED!$D$2:$D$1201, A7) -> 156 | C7: =SUMIF(CLEANED!$D$2:$D$1201, A7, CLEANED!$N$2:$N$1201) -> 151722.39 | D7: =AVERAGEIF(CLEANED!$D$2:$D$1201, A7, CLEANED!$N$2:$N$1201) -> 972.57942
A8: Printer | B8: =COUNTIF(CLEANED!$D$2:$D$1201, A8) -> 181 | C8: =SUMIF(CLEANED!$D$2:$D$1201, A8, CLEANED!$N$2:$N$1201) -> 195612.61 | D8: =AVERAGEIF(CLEANED!$D$2:$D$1201, A8, CLEANED!$N$2:$N$1201) -> 1080.7327
A9: Tablet | B9: =COUNTIF(CLEANED!$D$2:$D$1201, A9) -> 179 | C9: =SUMIF(CLEANED!$D$2:$D$1201, A9, CLEANED!$N$2:$N$1201) -> 186568.95 | D9: =AVERAGEIF(CLEANED!$D$2:$D$1201, A9, CLEANED!$N$2:$N$1201) -> 1042.2846
B11: ORDERS & REVENUE BY STATUS
A12: ORDER STATUS | B12: ORDER COUNT | C12: TOTAL REVENUE | D12: AVERAGE ORDER VALUE
A13: Shipped | B13: =COUNTIF(CLEANED!$I$2:$I$1201, A13) -> 235 | C13: =SUMIF(CLEANED!$I$2:$I$1201, A13, CLEANED!$N$2:$N$1201) -> 246159.58 | D13: =AVERAGEIF(CLEANED!$I$2:$I$1201, A13, CLEANED!$N$2:$N$1201) -> 1047.4876
A14: Delivered | B14: =COUNTIF(CLEANED!$I$2:$I$1201, A14) -> 231 | C14: =SUMIF(CLEANED!$I$2:$I$1201, A14, CLEANED!$N$2:$N$1201) -> 242600.32 | D14: =AVERAGEIF(CLEANED!$I$2:$I$1201, A14, CLEANED!$N$2:$N$1201) -> 1050.2178
A15: Pending | B15: =COUNTIF(CLEANED!$I$2:$I$1201, A15) -> 237 | C15: =SUMIF(CLEANED!$I$2:$I$1201, A15, CLEANED!$N$2:$N$1201) -> 256328.15 | D15: =AVERAGEIF(CLEANED!$I$2:$I$1201, A15, CLEANED!$N$2:$N$1201) -> 1081.5534
A16: Returned | B16: =COUNTIF(CLEANED!$I$2:$I$1201, A16) -> 247 | C16: =SUMIF(CLEANED!$I$2:$I$1201, A16, CLEANED!$N$2:$N$1201) -> 243277.7 | D16: =AVERAGEIF(CLEANED!$I$2:$I$1201, A16, CLEANED!$N$2:$N$1201) -> 984.92996
A17: Cancelled | B17: =COUNTIF(CLEANED!$I$2:$I$1201, A17) -> 250 | C17: =SUMIF(CLEANED!$I$2:$I$1201, A17, CLEANED!$N$2:$N$1201) -> 276396.21 | D17: =AVERAGEIF(CLEANED!$I$2:$I$1201, A17, CLEANED!$N$2:$N$1201) -> 1105.5848
B19: ORDERS & REVENUE BY PAYMENT METHOD
A20: PAYMENT METHOD | B20: ORDER COUNT | C20: TOTAL REVENUE | D20: AVERAGE ORDER VALUE
A21: Cash | B21: =COUNTIF(CLEANED!$H$2:$H$1201, A21) -> 246 | C21: =SUMIF(CLEANED!$H$2:$H$1201, A21, CLEANED!$N$2:$N$1201) -> 259786.29 | D21: =AVERAGEIF(CLEANED!$H$2:$H$1201, A21, CLEANED!$N$2:$N$1201) -> 1056.0418
A22: Credit Card | B22: =COUNTIF(CLEANED!$H$2:$H$1201, A22) -> 234 | C22: =SUMIF(CLEANED!$H$2:$H$1201, A22, CLEANED!$N$2:$N$1201) -> 263847.63 | D22: =AVERAGEIF(CLEANED!$H$2:$H$1201, A22, CLEANED!$N$2:$N$1201) -> 1127.554
A23: Debit Card | B23: =COUNTIF(CLEANED!$H$2:$H$1201, A23) -> 232 | C23: =SUMIF(CLEANED!$H$2:$H$1201, A23, CLEANED!$N$2:$N$1201) -> 232361.18 | D23: =AVERAGEIF(CLEANED!$H$2:$H$1201, A23, CLEANED!$N$2:$N$1201) -> 1001.5568
A24: Gift Card | B24: =COUNTIF(CLEANED!$H$2:$H$1201, A24) -> 230 | C24: =SUMIF(CLEANED!$H$2:$H$1201, A24, CLEANED!$N$2:$N$1201) -> 246323.92 | D24: =AVERAGEIF(CLEANED!$H$2:$H$1201, A24, CLEANED!$N$2:$N$1201) -> 1070.9736
A25: Online | B25: =COUNTIF(CLEANED!$H$2:$H$1201, A25) -> 258 | C25: =SUMIF(CLEANED!$H$2:$H$1201, A25, CLEANED!$N$2:$N$1201) -> 262442.94 | D25: =AVERAGEIF(CLEANED!$H$2:$H$1201, A25, CLEANED!$N$2:$N$1201) -> 1017.2207
B27: ORDERS & REVENUE BY REFERRAL SOURCE
A28: REFERRAL SOURCE | B28: ORDER COUNT | C28: TOTAL REVENUE | D28: AVERGE ORDER VALUE
A29: Email | B29: =COUNTIF(CLEANED!$M$2:$M$1201, A29) -> 250 | C29: =SUMIF(CLEANED!$M$2:$M$1201, A29, CLEANED!$N$2:$N$1201) -> 261808.55 | D29: =AVERAGEIF(CLEANED!$M$2:$M$1201, A29, CLEANED!$N$2:$N$1201) -> 1047.2342
A30: Facebook | B30: =COUNTIF(CLEANED!$M$2:$M$1201, A30) -> 228 | C30: =SUMIF(CLEANED!$M$2:$M$1201, A30, CLEANED!$N$2:$N$1201) -> 250410.9 | D30: =AVERAGEIF(CLEANED!$M$2:$M$1201, A30, CLEANED!$N$2:$N$1201) -> 1098.2934
A31: Google | B31: =COUNTIF(CLEANED!$M$2:$M$1201, A31) -> 241 | C31: =SUMIF(CLEANED!$M$2:$M$1201, A31, CLEANED!$N$2:$N$1201) -> 250441.48 | D31: =AVERAGEIF(CLEANED!$M$2:$M$1201, A31, CLEANED!$N$2:$N$1201) -> 1039.1763
A32: Instagram | B32: =COUNTIF(CLEANED!$M$2:$M$1201, A32) -> 259 | C32: =SUMIF(CLEANED!$M$2:$M$1201, A32, CLEANED!$N$2:$N$1201) -> 275285.45 | D32: =AVERAGEIF(CLEANED!$M$2:$M$1201, A32, CLEANED!$N$2:$N$1201) -> 1062.8782
A33: Referral | B33: =COUNTIF(CLEANED!$M$2:$M$1201, A33) -> 222 | C33: =SUMIF(CLEANED!$M$2:$M$1201, A33, CLEANED!$N$2:$N$1201) -> 226815.58 | D33: =AVERAGEIF(CLEANED!$M$2:$M$1201, A33, CLEANED!$N$2:$N$1201) -> 1021.6918

Sheet KEY OBSERVATION
B1: KEY OBSERVATION
A2: 1 | B2: The dataset contains 1,200 orders from January 2023 to June 2025.
A4: 2 | B4: Chair generated the highest revenue ($195,620.11), while Phone generated the lowest ($151,722.39).
A6: 3 | B6: Eight orders were flagged as outliers using the IQR method, all falling between $3,334 and $3,456.
A8: 4 | B8: The Average Total Price ($1,053.97) is higher than the median ($823.62), indicating the presence of relatively high-value orders.
A10: 5 | B10: UnitPrice shows the strongest correlation with TotalPrice (0.72) while Quantity and UnitPrice show almost no correlation (0.01).
A12: 6 | B12: Instagram is the leading referral source, bringing in the highest number of orders among all channels suggesting it's currently the most effective customer acquisition channel.
A14: 7 | B14: The average order value ($1,053.97) is notably higher than the median ($823.62), indicating that a small number of high-value orders are pulling the average upward.
A16: 8 | B16: Cancelled and Returned orders together account for nearly 41% of all orders, which may be worth investigating further as a potential fulfillment or customer satisfaction issue.
